Workbook

Sheet Detalle de Costos
D3: Costos por paquete de trabajo
A6: Modelo de análisis de conversión para e-commerce
A7: Código | B7: Paquete de Trabajo
A8: Semanas | C8: 1 | D8: 2 | E8: 3 | F8: 4 | G8: 5 | H8: 6 | I8: 7 | J8: 8 | K8: 9 | L8: 10 | M8: 11 | N8: 12
A9: Componente 1: Sprint 1 – Comprender el negocio y los datos | C9: 12000 | D9: 12000 | E9: 18000 | F9: 18000 | G9: 33000 | H9: 33000 | I9: 38000 | J9: 40000 | K9: 27000 | L9: 27000 | M9: 21000 | N9: 21000
A10: 1.1.1.1 | B10: Paquete de trabajo: Análisis del problema
A11: 1.1.1.1.1 | B11: Actividad: Revisar acta constitutiva y contexto del e-commerce | C11: 1000
A12: 1.1.1.1.2 | B12: Actividad: Definir problemática de negocio (baja conversión) | C12: 2000
A13: 1.1.1.1.3 | B13: Actividad: Identificar decisiones de negocio que apoyará el modelo | C13: 500
A14: 1.2.1.1 | B14: Paquete de trabajo: Exploración de datos
A15: 1.2.1.1.1 | B15: Actividad: Descargar dataset y revisar estructura general | C15: 2500
A16: 1.2.1.1.2 | B16: Actividad: Analizar distribución de eventos (view, cart, purchase) | C16: 2000
A17: 1.2.1.1.3 | B17: Actividad: Detectar valores nulos y patrones generales | C17: 1000
A18: Componente 2: Selección del subset y métricas iniciales
A19: 2.1.1.1 | B19: Paquete de trabajo: Selección del subset
A20: 2.1.1.1.1 | B20: Actividad: Definir tamaño del subset | C20: 2000
A21: 2.1.1.1.2 | B21: Actividad: Aplicar muestreo del dataset | C21: 1000
A22: 2.1.1.1.3 | B22: Actividad: Validar representatividad del subset | D22: 900
A23: 2.2.1.1 | B23: Paquete de trabajo: Documentación de resultados
A24: 2.2.1.1.1 | B24: Actividad: Elaborar análisis exploratorio | D24: 3000
A25: 2.2.1.1.2 | B25: Actividad: Calcular métricas iniciales de conversión | D25: 5000
A26: 2.2.1.1.3 | B26: Actividad: Documentar funnel de conversión | D26: 3000
A27: Componente 3: Cierre del Sprint
A28: 3.1.1.1 | B28: Paquete de trabajo: Revisión final
A29: 3.1.1.1.1 | B29: Actividad: Revisión final y validación del Sprint 1 | C29: 0 | D29: 100
B30: TOTAL | C30: =SUM(C10:C29) -> 12000 | D30: =SUM(D10:D29) -> 12000 | E30: =SUM(E10:E29) -> 0 | F30: =SUM(F10:F29) -> 0 | G30: =SUM(G10:G29) -> 0 | H30: =SUM(H10:H29) -> 0 | I30: =SUM(I10:I29) -> 0 | J30: =SUM(J10:J29) -> 0 | ... N30: =SUM(N10:N29) -> 0

Sheet Plantilla Curva S
C7: Curva S de Recursos
C9: Proyecto: | D9: Modelo de análisis de conversión para e-commerce
C10: ID: | D10: Código identificador del proyecto.
C11: Fecha de Inicio | D11: 16 de febrero del 2026 | F11: Fecha Fin: | H11: 30 de mayo del 2026 | K11: Fecha de Corte: | M11: Fecha a la cual se reporta el costo real.
D13: Trimestre
D14: 1 | E14: 2 | F14: 3 | G14: 4 | H14: 5 | I14: 6 | J14: 7 | K14: 8 | L14: 9 | M14: 10 | N14: 11 | O14: 12
C15: Valor Planificado | D15: ='Detalle de Costos'!C9 -> 12000 | E15: ='Detalle de Costos'!D9 -> 12000 | F15: ='Detalle de Costos'!E9 -> 18000 | G15: ='Detalle de Costos'!F9 -> 18000 | H15: ='Detalle de Costos'!G9 -> 33000 | I15: ='Detalle de Costos'!H9 -> 33000 | J15: ='Detalle de Costos'!I9 -> 38000 | K15: ='Detalle de Costos'!J9 -> 40000 | ... O15: ='Detalle de Costos'!N9 -> 21000
C16: Valor Planificado Acumulado | D16: =D15 -> 12000 | E16: =E15+D16 -> 24000 | F16: =F15+E16 -> 42000 | G16: =G15+F16 -> 60000 | H16: =H15+G16 -> 93000 | I16: =I15+H16 -> 126000 | J16: =J15+I16 -> 164000 | K16: =K15+J16 -> 204000 | L16: =L15+K16 -> 231000 | ... O16: =O15+N16 -> 300000
C17: Costo Real | D17: ='Detalle de Costos'!C30 -> 12000 | E17: ='Detalle de Costos'!D30 -> 12000 | F17: 18000 | G17: 18000 | H17: ='Detalle de Costos'!G30 -> 0 | I17: ='Detalle de Costos'!H30 -> 0 | J17: ='Detalle de Costos'!I30 -> 0 | K17: ='Detalle de Costos'!J30 -> 0 | L17: ='Detalle de Costos'!K30 -> 0 | M17: ='Detalle de Costos'!L30 -> 0 | N17: ='Detalle de Costos'!M30 -> 0 | O17: ='Detalle de Costos'!N30 -> 0
C18: Costo Real Acumulado | D18: =D17 -> 12000 | E18: =D18+E17 -> 24000 | F18: =E18+F17 -> 42000 | G18: =F18+G17 -> 60000 | H18: =G18+H17 -> 60000 | I18: =I17+H17 -> 0 | J18: =J17+I17 -> 0 | K18: =K17+J17 -> 0 | L18: =L17+K17 -> 0 | M18: =M17+L17 -> 0 | N18: =N17+M17 -> 0 | O18: =O17+N17 -> 0

Sheet Ejemplo
C7: Curva S de Recursos
C9: Proyecto: | D9: Apoyo Educativo
C10: ID: | D10: HT2011-12
C11: Fecha de Inicio | D11: 40695 | F11: Fecha Fin: | H11: 41455 | K11: Fecha de Corte: | M11: 40908
D13: Año 2012
D14: Mes 1 | E14: Mes 2 | F14: Mes 3 | G14: Mes 4 | H14: Mes 5 | I14: Mes 6 | J14: Mes 7 | K14: Mes 8 | L14: Mes 9 | M14: Mes 10 | N14: Mes 11 | O14: Mes 12
C15: Valor Planificado | D15: 20000 | E15: 40000 | F15: 60000 | G15: 80000 | H15: 120000 | I15: 140000 | J15: 160000 | K15: 180000 | L15: 180000 | M15: 120000 | N15: 80000 | O15: 40000
C16: Valor Planificado Acumulado | D16: =D15 -> 20000 | E16: =D16+E15 -> 60000 | F16: =E16+F15 -> 120000 | G16: =F16+G15 -> 200000 | H16: =G16+H15 -> 320000 | I16: =H16+I15 -> 460000 | J16: =I16+J15 -> 620000 | K16: =J16+K15 -> 800000 | L16: =K16+L15 -> 980000 | ... O16: =N16+O15 -> 1220000
C17: Costo Real | D17: 20000 | E17: 20000 | F17: 40000 | G17: 60000 | H17: 80000 | I17: 100000 | J17: 150000
C18: Costo Real Acumulado | D18: =D17 -> 20000 | E18: =D18+E17 -> 40000 | F18: =E18+F17 -> 80000 | G18: =F18+G17 -> 140000 | H18: =G18+H17 -> 220000 | I18: =H18+I17 -> 320000 | J18: =I18+J17 -> 470000

Sheet Hoja1
D2: Costos por paquete de trabajo
A5: Nombre del Proyecto
A6: Código | B6: Paquete de Trabajo
A7: Meses | C7: 1 | D7: 2 | E7: 3 | F7: 4 | G7: 5 | H7: 6 | I7: 7 | J7: 8 | K7: 9 | L7: 10 | M7: 11 | N7: 12 | O7: 13 | P7: 14 | Q7: 15 | R7: 16 | S7: 17 | T7: 18 | U7: 19 | V7: 20 | W7: 21 | X7: 22 | Y7: 23 | Z7: 24 | AA7: 25 | AB7: 26 | AC7: 27 | AD7: 28 | AE7: 29 | AF7: 30 | AG7: 31 | AH7: 32 | AI7: 33 | AJ7: 34 | AK7: 35 | AL7: 36 | AM7: 37 | AN7: 38 | AO7: 39 | AP7: 40 | AQ7: 41 | AR7: 42 | AS7: 43 | AT7: 44 | AU7: 45 | AV7: 46 | AW7: 47 | AX7: 48 | AY7: 49 | AZ7: 50 | BA7: 51 | BB7: 52 | BC7: 53 | BD7: 54 | BE7: 55 | BF7: 56 | BG7: 57 | BH7: 58 | BI7: 59 | BJ7: 60
A8: Componente 1 | C8: 10000
A9: 1.1.1.1 | B9: Paquete de trabajo: Análisis del problema
A10: 1.1.1.1.1 | B10: Actividad: Revisar acta constitutiva y contexto del e-commerce
A11: 1.1.1.1.2 | B11: Actividad: Definir problemática de negocio (baja conversión)
A12: 1.1.1.1.3 | B12: Actividad: Identificar decisiones de negocio que apoyará el modelo
A13: 1.2.1.1 | B13: Paquete de trabajo: Exploración de datos
A14: 1.2.1.1.1 | B14: Actividad: Descargar dataset y revisar estructura general
A15: 1.2.1.1.2 | B15: Actividad: Analizar distribución de eventos (view, cart, purchase)
A16: 1.2.1.1.3 | B16: Actividad: Detectar valores nulos y patrones generales
A17: 1.2.1.3
A18: 1.2.2.1
A19: 1.2.2.2
A20: 1.2.2.3
A21: Componente 2
A22: 2.1.1.1 | B22: Paquete de trabajo
A23: 2.1.1.2
A24: 2.1.1.3
A25: 2.1.2.1
A26: 2.1.2.2
A27: 2.1.2.3
A28: 2.2.1.1
A29: 2.2.1.2
A30: 2.2.1.3
A31: 2.2.2.1
A32: 2.2.2.2
A33: 2.2.2.3
A34: Componente 3
A35: 2.1.1.1 | B35: Paquete de trabajo
A36: 2.1.1.2
A37: 2.1.1.3
A38: 2.1.2.1
A39: 2.1.2.2
A40: 2.1.2.3
A41: 2.2.1.1
A42: 2.2.1.2
A43: 2.2.1.3
...

Sheet SPRINT 1
A5: Curva S de Recursos
A7: Proyecto: | B7: Modelo de análisis de conversión para e-commerce
A8: ID: | B8: Código identificador del proyecto.
A9: Fecha de Inicio | B9: 16 de febrero del 2026 | D9: Fecha Fin: | F9: 30 de mayo del 2026 | I9: Fecha de Corte: | K9: Fecha a la cual se reporta el costo real.
B11: Trimestre
B12: 1 | C12: 2 | D12: 3 | E12: 4 | F12: 5 | G12: 6 | H12: 7 | I12: 8 | J12: 9 | K12: 10 | L12: 11 | M12: 12
A13: Valor Planificado | B13: 12000 | C13: 12000 | D13: 18000 | E13: 18000 | F13: 33000 | G13: 33000 | H13: 38000 | I13: 40000 | J13: 27000 | K13: 27000 | L13: 21000 | M13: 21000
A14: Valor Planificado Acumulado | B14: =B13 -> 12000 | C14: =C13+B14 -> 24000 | D14: =D13+C14 -> 42000 | E14: =E13+D14 -> 60000 | F14: =F13+E14 -> 93000 | G14: =G13+F14 -> 126000 | H14: =H13+G14 -> 164000 | I14: =I13+H14 -> 204000 | J14: =J13+I14 -> 231000 | ... M14: =M13+L14 -> 300000
A15: Costo Real | B15: =B13 -> 12000 | C15: =C13 -> 12000 | D15: 0 | E15: 0 | F15: ='Detalle de Costos'!E28 | G15: ='Detalle de Costos'!F28 | H15: ='Detalle de Costos'!G28 | I15: ='Detalle de Costos'!H28 | J15: ='Detalle de Costos'!I28 | K15: ='Detalle de Costos'!J28 | L15: ='Detalle de Costos'!K28 | M15: 0
A16: Costo Real Acumulado | B16: =B15 -> 12000 | C16: =B16+C15 -> 24000 | D16: 0 | E16: 0 | F16: 0 | G16: =G15+F15 -> 0 | H16: =H15+G15 -> 0 | I16: =I15+H15 -> 0 | J16: =J15+I15 -> 0 | K16: =K15+J15 -> 0 | L16: =L15+K15 -> 0 | M16: =M15+L15 -> 0

Sheet SPRINT 2
C7: Curva S de Recursos
C9: Proyecto: | D9: Modelo de análisis de conversión para e-commerce
C10: ID: | D10: Código identificador del proyecto.
C11: Fecha de Inicio | D11: 16 de febrero del 2026 | F11: Fecha Fin: | H11: 30 de mayo del 2026 | K11: Fecha de Corte: | M11: Fecha a la cual se reporta el costo real.
D13: Trimestre
D14: 1 | E14: 2 | F14: 3 | G14: 4 | H14: 5 | I14: 6 | J14: 7 | K14: 8 | L14: 9 | M14: 10 | N14: 11 | O14: 12
C15: Valor Planificado | D15: ='Detalle de Costos'!C9 -> 12000 | E15: ='Detalle de Costos'!D9 -> 12000 | F15: ='Detalle de Costos'!E9 -> 18000 | G15: ='Detalle de Costos'!F9 -> 18000 | H15: ='Detalle de Costos'!G9 -> 33000 | I15: ='Detalle de Costos'!H9 -> 33000 | J15: ='Detalle de Costos'!I9 -> 38000 | K15: ='Detalle de Costos'!J9 -> 40000 | ... O15: ='Detalle de Costos'!N9 -> 21000
C16: Valor Planificado Acumulado | D16: =D15 -> 12000 | E16: =E15+D16 -> 24000 | F16: =F15+E16 -> 42000 | G16: =G15+F16 -> 60000 | H16: =H15+G16 -> 93000 | I16: =I15+H16 -> 126000 | J16: =J15+I16 -> 164000 | K16: =K15+J16 -> 204000 | L16: =L15+K16 -> 231000 | ... O16: =O15+N16 -> 300000
C17: Costo Real | D17: ='Detalle de Costos'!C30 -> 12000 | E17: ='Detalle de Costos'!D30 -> 12000 | F17: 18000 | G17: 18000 | H17: ='Detalle de Costos'!G30 -> 0 | I17: ='Detalle de Costos'!H30 -> 0 | J17: ='Detalle de Costos'!I30 -> 0 | K17: ='Detalle de Costos'!J30 -> 0 | L17: ='Detalle de Costos'!K30 -> 0 | M17: ='Detalle de Costos'!L30 -> 0 | N17: ='Detalle de Costos'!M30 -> 0 | O17: ='Detalle de Costos'!N30 -> 0
C18: Costo Real Acumulado | D18: =D17 -> 12000 | E18: =D18+E17 -> 24000 | F18: =E18+F17 -> 42000 | G18: =F18+G17 -> 60000 | H18: 0 | I18: =I17+H17 -> 0 | J18: =J17+I17 -> 0 | K18: =K17+J17 -> 0 | L18: =L17+K17 -> 0 | M18: =M17+L17 -> 0 | N18: =N17+M17 -> 0 | O18: =O17+N17 -> 0

Sheet SPRINT 3
C7: Curva S de Recursos
C9: Proyecto: | D9: Modelo de análisis de conversión para e-commerce
C10: ID: | D10: Código identificador del proyecto.
C11: Fecha de Inicio | D11: 16 de febrero del 2026 | F11: Fecha Fin: | H11: 30 de mayo del 2026 | K11: Fecha de Corte: | M11: Fecha a la cual se reporta el costo real.
D13: Trimestre
D14: 1 | E14: 2 | F14: 3 | G14: 4 | H14: 5 | I14: 6 | J14: 7 | K14: 8 | L14: 9 | M14: 10 | N14: 11 | O14: 12
C15: Valor Planificado | D15: ='Detalle de Costos'!C9 -> 12000 | E15: ='Detalle de Costos'!D9 -> 12000 | F15: ='Detalle de Costos'!E9 -> 18000 | G15: ='Detalle de Costos'!F9 -> 18000 | H15: ='Detalle de Costos'!G9 -> 33000 | I15: ='Detalle de Costos'!H9 -> 33000 | J15: ='Detalle de Costos'!I9 -> 38000 | K15: ='Detalle de Costos'!J9 -> 40000 | ... O15: ='Detalle de Costos'!N9 -> 21000
C16: Valor Planificado Acumulado | D16: =D15 -> 12000 | E16: =E15+D16 -> 24000 | F16: =F15+E16 -> 42000 | G16: =G15+F16 -> 60000 | H16: =H15+G16 -> 93000 | I16: =I15+H16 -> 126000 | J16: =J15+I16 -> 164000 | K16: =K15+J16 -> 204000 | L16: =L15+K16 -> 231000 | ... O16: =O15+N16 -> 300000
C17: Costo Real | D17: ='Detalle de Costos'!C30 -> 12000 | E17: ='Detalle de Costos'!D30 -> 12000 | F17: 18000 | G17: 18000 | H17: 33000 | I17: 33000 | J17: ='Detalle de Costos'!I30 -> 0 | K17: ='Detalle de Costos'!J30 -> 0 | L17: ='Detalle de Costos'!K30 -> 0 | M17: ='Detalle de Costos'!L30 -> 0 | N17: ='Detalle de Costos'!M30 -> 0 | O17: ='Detalle de Costos'!N30 -> 0
C18: Costo Real Acumulado | D18: =D17 -> 12000 | E18: =D18+E17 -> 24000 | F18: =E18+F17 -> 42000 | G18: =F18+G17 -> 60000 | H18: =G18+H17 -> 93000 | I18: =I17+H18 -> 126000 | J18: =J17+I18 -> 126000 | K18: =K17+J17 -> 0 | L18: =L17+K17 -> 0 | M18: =M17+L17 -> 0 | N18: =N17+M17 -> 0 | O18: =O17+N17 -> 0

Sheet SPRINT 4
C7: Curva S de Recursos
C9: Proyecto: | D9: Modelo de análisis de conversión para e-commerce
C10: ID: | D10: Código identificador del proyecto.
C11: Fecha de Inicio | D11: 16 de febrero del 2026 | F11: Fecha Fin: | H11: 30 de mayo del 2026 | K11: Fecha de Corte: | M11: 46134
D13: Trimestre
D14: 1 | E14: 2 | F14: 3 | G14: 4 | H14: 5 | I14: 6 | J14: 7 | K14: 8 | L14: 9 | M14: 10 | N14: 11 | O14: 12
C15: Valor Planificado | D15: ='Detalle de Costos'!C9 -> 12000 | E15: ='Detalle de Costos'!D9 -> 12000 | F15: ='Detalle de Costos'!E9 -> 18000 | G15: ='Detalle de Costos'!F9 -> 18000 | H15: ='Detalle de Costos'!G9 -> 33000 | I15: ='Detalle de Costos'!H9 -> 33000 | J15: ='Detalle de Costos'!I9 -> 38000 | K15: ='Detalle de Costos'!J9 -> 40000 | ... O15: ='Detalle de Costos'!N9 -> 21000
C16: Valor Planificado Acumulado | D16: =D15 -> 12000 | E16: =E15+D16 -> 24000 | F16: =F15+E16 -> 42000 | G16: =G15+F16 -> 60000 | H16: =H15+G16 -> 93000 | I16: =I15+H16 -> 126000 | J16: =J15+I16 -> 164000 | K16: =K15+J16 -> 204000 | L16: =L15+K16 -> 231000 | ... O16: =O15+N16 -> 300000
C17: Costo Real | D17: ='Detalle de Costos'!C30 -> 12000 | E17: ='Detalle de Costos'!D30 -> 12000 | F17: 18000 | G17: 18000 | H17: 33000 | I17: 33000 | J17: 38000 | K17: 40000 | L17: ='Detalle de Costos'!K30 -> 0 | M17: ='Detalle de Costos'!L30 -> 0 | N17: ='Detalle de Costos'!M30 -> 0 | O17: ='Detalle de Costos'!N30 -> 0
C18: Costo Real Acumulado | D18: =D17 -> 12000 | E18: =D18+E17 -> 24000 | F18: =E18+F17 -> 42000 | G18: =F18+G17 -> 60000 | H18: =G18+H17 -> 93000 | I18: =I17+H18 -> 126000 | J18: =J17+I18 -> 164000 | K18: =K17+J18 -> 204000 | L18: =L17+K18 -> 204000 | M18: =M17+L17 -> 0 | N18: =N17+M17 -> 0 | O18: =O17+N17 -> 0
